<?xml version="1.0"?>
<robot name="walle">


  <material name="blue">
    <color rgba="0 0 0.8 1"/>
  </material>

  <material name="white">
    <color rgba="1 1 1 1"/>
  </material>


  <link name="base_link">
    <origin rpy="0 0 0" xyz="0 0 0.1"/> 
    <visual>
      <geometry>
        <box size="0.4 0.2 0.1"/>
      </geometry>
      <origin rpy="0 0 0" xyz="0 0 0"/>
      <material name="white"/>
    </visual>
    <collision>
      <geometry>
        <box size="0.4 0.2 0.1"/>
      </geometry>
    </collision>
  </link>

  <link name="right_wheel">
    <origin rpy="0 0 0" xyz="0.1 0.13 0.1"/>
    <visual>
      <geometry>
        <cylinder length="0.05" radius="0.1"/>
      </geometry>
      <origin rpy="1.57075 0 0" xyz="0 0 0"/>  
    </visual>
    <collision>
      <geometry>
        <cylinder length="0.05" radius="0.1"/>
      </geometry>
      <origin rpy="1.57075 0 0" xyz="0 0 0"/>
    </collision>
  </link>

  <link name="left_wheel">
    <origin rpy="0 0 0" xyz="0.1 -0.13 0.1"/>
    <visual>
      <geometry>
        <cylinder length="0.05" radius="0.1"/>
      </geometry>
      <origin rpy="1.57075 0 0" xyz="0 0 0"/>
    </visual>
    <collision>
      <geometry>
        <cylinder length="0.05" radius="0.1"/>
      </geometry>
      <origin rpy="1.57075 0 0" xyz="0 0 0"/>
    </collision>
  </link>

  <link name="castor">
    <visual>
      <geometry>
        <sphere radius="0.05"/>
      </geometry>
      <origin rpy="0 0 0" xyz="0 0 0"/>
    </visual>
    <collision>
      <geometry>
        <sphere radius="0.05"/>
      </geometry>
    </collision>
  </link>

  <link name="castor_psi">
    <visual>
      <geometry>
        <sphere radius="0.05"/>
      </geometry>
      <origin rpy="0 0 0" xyz="0 0 0"/>
    </visual>
    <collision>
      <geometry>
        <sphere radius="0.05"/>
      </geometry>
    </collision>
  </link>

  <link name="castor_theta">
    <visual>
      <geometry>
        <sphere radius="0.05"/>
      </geometry>
      <origin rpy="0 0 0" xyz="0 0 0"/>
    </visual>
    <collision>
      <geometry>
        <sphere radius="0.05"/>
      </geometry>
    </collision>
  </link>

  <link name="castor_back">
    <visual>
      <geometry>
        <sphere radius="0.05"/>
      </geometry>
      <origin rpy="0 0 0" xyz="0 0 0"/>
    </visual>
    <collision>
      <geometry>
        <sphere radius="0.05"/>
      </geometry>
    </collision>
  </link>

  <link name="castor_psi_back">
    <visual>
      <geometry>
        <sphere radius="0.05"/>
      </geometry>
      <origin rpy="0 0 0" xyz="0 0 0"/>
    </visual>
    <collision>
      <geometry>
        <sphere radius="0.05"/>
      </geometry>
    </collision>
  </link>

  <link name="castor_theta_back">
    <visual>
      <geometry>
        <sphere radius="0.05"/>
      </geometry>
      <origin rpy="0 0 0" xyz="0 0 0"/>
    </visual>
    <collision>
      <geometry>
        <sphere radius="0.05"/>
      </geometry>
    </collision>
  </link>

  <joint name="base_to_right_wheel" type="continuous">
    <parent link="base_link"/>
    <child link="right_wheel"/>
    <axis xyz="0 1 0" rpy="0 0 0"/>
    <origin xyz="0 0.125 0"/>
  </joint>

  <joint name="base_to_left_wheel" type="continuous">
    <parent link="base_link"/>
    <child link="left_wheel"/>
    <axis xyz="0 1 0" rpy="0 0 0"/>
    <origin xyz="0 -0.125 0"/>
  </joint>  

  <joint name="base_to_castor" type="continuous">
    <parent link="base_link"/>
    <child link="castor"/>
    <axis rpy="0 0 0" xyz="0 1 0"/>
    <origin xyz="0.15 0 -0.05"/>
  </joint>  


  <joint name="castor_castorPsi" type="continuous">
    <parent link="castor"/>
    <child link="castor_psi"/>
    <axis xyz="1 0 0" rpy="0 0 0"/>
    <origin xyz="0 0 0"/>
  </joint> 


  <joint name="castorPsi_castorTheta" type="continuous">
    <parent link="castor_psi"/>
    <child link="castor_theta"/>
    <axis xyz="0 0 1" rpy="0 0 0"/>
    <origin xyz="0 0 0"/>
  </joint> 

  <joint name="base_to_castorBack" type="continuous">
    <parent link="base_link"/>
    <child link="castor_back"/>
    <axis rpy="0 0 0" xyz="0 1 0"/>
    <origin xyz="-0.15 0 -0.05"/>
  </joint>  


  <joint name="castor_castorPsiBack" type="continuous">
    <parent link="castor_back"/>
    <child link="castor_psi_back"/>
    <axis xyz="1 0 0" rpy="0 0 0"/>
    <origin xyz="0 0 0"/>
  </joint> 


  <joint name="castorPsi_castorThetaBack" type="continuous">
    <parent link="castor_psi_back"/>
    <child link="castor_theta_back"/>
    <axis xyz="0 0 1" rpy="0 0 0"/>
    <origin xyz="0 0 0"/>
  </joint> 




</robot>